Workbook

Sheet Monthly Dashboard
A1: CONIC — MONTHLY DASHBOARD
A3: Month | B3: September | C3: Year | D3: 2026
A5: Online Sales | D5: Cash Sales | G5: Total Sales
A6: ='Monthly Summary'!B5 -> 226284 | D6: ='Monthly Summary'!B6 -> 18570 | G6: ='Monthly Summary'!B7 -> 244854
A8: Total Purchases | D8: Total Expenses | G8: Online Balance
A9: ='Monthly Summary'!B19 -> 193826 | D9: ='Monthly Summary'!B25 -> 23242 | G9: ='Monthly Summary'!B28 -> 9216
A11: Cash Balance | D11: Total Balance | G11: Net Amount
A12: ='Monthly Summary'!B30 -> 18570 | D12: ='Monthly Summary'!B31 -> 27786 | G12: ='Monthly Summary'!B33 -> 27786
A15: Latest Day | B15: Sales | C15: Expenses | D15: Net | E15: Balance | H15: Latest Date
A16: Latest Day | B16: =IFERROR(SUMIFS('Daily Sales & Expenses'!$D$2:$D$494,'Daily Sales & Expenses'!$A$2:$A$494,MAX('Daily Sales & Expenses'!$A$2:$A$494)),0) -> 6399 | C16: =IFERROR(SUMIFS('Daily Sales & Expenses'!$I$2:$I$494,'Daily Sales & Expenses'!$A$2:$A$494,MAX('Daily Sales & Expenses'!$A$2:$A$494)),0) -> 5095 | D16: =B16-C16 -> 1304 | E16: =IFERROR(SUMIFS('Daily Sales & Expenses'!$N$2:$N$494,'Daily Sales & Expenses'!$A$2:$A$494,MAX('Daily Sales & Expenses'!$A$2:$A$494)),0) -> 27786 | H16: =IFERROR(SUMIFS('Daily Sales & Expenses'!$A$2:$A$494,'Daily Sales & Expenses'!$A$2:$A$494,MAX('Daily Sales & Expenses'!$A$2:$A$494)),0) -> 46289
A17: Latest-day figures come from the most recent dated entry inside the selected month.

Sheet Yearly Dashboard
A1: CONIC — YEARLY DASHBOARD
A3: Year | B3: 2026
A5: Month | B5: Total Sales | C5: Total Purchases | D5: Total Expenses | E5: Net Amount | F5: Closing Balance
A6: January | B6: =SUMIFS('Daily Sales & Expenses'!$D$2:$D$495,'Daily Sales & Expenses'!$A$2:$A$495,">="&DATE($B$3,1,1),'Daily Sales & Expenses'!$A$2:$A$495,"<"&EDATE(DATE($B$3,1,1),1)) -> 0 | C6: =SUMIFS('Weekly Purchases'!$M$2:$M$503,'Weekly Purchases'!$A$2:$A$503,">="&DATE($B$3,1,1),'Weekly Purchases'!$A$2:$A$503,"<"&EDATE(DATE($B$3,1,1),1)) -> 0 | D6: =SUMIFS('Daily Sales & Expenses'!$I$2:$I$495,'Daily Sales & Expenses'!$A$2:$A$495,">="&DATE($B$3,1,1),'Daily Sales & Expenses'!$A$2:$A$495,"<"&EDATE(DATE($B$3,1,1),1)) -> 0 | E6: =B6-C6-D6 -> 0 | F6: =Settings!$B$3+Settings!$B$4+SUMIFS('Daily Sales & Expenses'!$D$2:$D$495,'Daily Sales & Expenses'!$A$2:$A$495,"<"&EDATE(DATE($B$3,1,1),1))-SUMIFS('Daily Sales & Expenses'!$J$2:$J$495,'Daily Sales & Expenses'!$A$2:$A$495,"<"&EDATE(DATE($B$3,1,1),1))-SUMIFS('Daily Sales & Expenses'!$K$2:$K$495,'Daily Sales & Expenses'!$A$2:$A$495,"<"&EDATE(DATE($B$3,1,1),1))-SUMIFS('Weekly Purchases'!$N$2:$N$503,'Weekly Purchases'!$B$2:$B$503,"<"&EDATE(DATE($B$3,1,1),1),'Weekly Purchases'!$B$2:$B$503,"<>")-SUMIFS('Weekly Purchases'!$N$2:$N$503,'Weekly Purchases'!$B$2:$B$503,"",'Weekly Purchases'!$A$2:$A$503,"<"&EDATE(DATE($B$3,1,1),1))-SUMIFS('Weekly Purchases'!$O$2:$O$503,'Weekly Purchases'!$B$2:$B$503,"<"&EDATE(DATE($B$3,1,1),1),'Weekly Purchases'!$B$2:$B$503,"<>")-SUMIFS('Weekly Purchases'!$O$2:$O$503,'Weekly Purchases'!$B$2:$B$503,"",'Weekly Purchases'!$A$2:$A$503,"<"&EDATE(DATE($B$3,1,1),1)) -> 0
A7: February | B7: =SUMIFS('Daily Sales & Expenses'!$D$2:$D$495,'Daily Sales & Expenses'!$A$2:$A$495,">="&DATE($B$3,2,1),'Daily Sales & Expenses'!$A$2:$A$495,"<"&EDATE(DATE($B$3,2,1),1)) -> 0 | C7: =SUMIFS('Weekly Purchases'!$M$2:$M$503,'Weekly Purchases'!$A$2:$A$503,">="&DATE($B$3,2,1),'Weekly Purchases'!$A$2:$A$503,"<"&EDATE(DATE($B$3,2,1),1)) -> 0 | D7: =SUMIFS('Daily Sales & Expenses'!$I$2:$I$495,'Daily Sales & Expenses'!$A$2:$A$495,">="&DATE($B$3,2,1),'Daily Sales & Expenses'!$A$2:$A$495,"<"&EDATE(DATE($B$3,2,1),1)) -> 0 | E7: =B7-C7-D7 -> 0 | F7: =Settings!$B$3+Settings!$B$4+SUMIFS('Daily Sales & Expenses'!$D$2:$D$495,'Daily Sales & Expenses'!$A$2:$A$495,"<"&EDATE(DATE($B$3,2,1),1))-SUMIFS('Daily Sales & Expenses'!$J$2:$J$495,'Daily Sales & Expenses'!$A$2:$A$495,"<"&EDATE(DATE($B$3,2,1),1))-SUMIFS('Daily Sales & Expenses'!$K$2:$K$495,'Daily Sales & Expenses'!$A$2:$A$495,"<"&EDATE(DATE($B$3,2,1),1))-SUMIFS('Weekly Purchases'!$N$2:$N$503,'Weekly Purchases'!$B$2:$B$503,"<"&EDATE(DATE($B$3,2,1),1),'Weekly Purchases'!$B$2:$B$503,"<>")-SUMIFS('Weekly Purchases'!$N$2:$N$503,'Weekly Purchases'!$B$2:$B$503,"",'Weekly Purchases'!$A$2:$A$503,"<"&EDATE(DATE($B$3,2,1),1))-SUMIFS('Weekly Purchases'!$O$2:$O$503,'Weekly Purchases'!$B$2:$B$503,"<"&EDATE(DATE($B$3,2,1),1),'Weekly Purchases'!$B$2:$B$503,"<>")-SUMIFS('Weekly Purchases'!$O$2:$O$503,'Weekly Purchases'!$B$2:$B$503,"",'Weekly Purchases'!$A$2:$A$503,"<"&EDATE(DATE($B$3,2,1),1)) -> 0
A8: March | B8: =SUMIFS('Daily Sales & Expenses'!$D$2:$D$495,'Daily Sales & Expenses'!$A$2:$A$495,">="&DATE($B$3,3,1),'Daily Sales & Expenses'!$A$2:$A$495,"<"&EDATE(DATE($B$3,3,1),1)) -> 0 | C8: =SUMIFS('Weekly Purchases'!$M$2:$M$503,'Weekly Purchases'!$A$2:$A$503,">="&DATE($B$3,3,1),'Weekly Purchases'!$A$2:$A$503,"<"&EDATE(DATE($B$3,3,1),1)) -> 0 | D8: =SUMIFS('Daily Sales & Expenses'!$I$2:$I$495,'Daily Sales & Expenses'!$A$2:$A$495,">="&DATE($B$3,3,1),'Daily Sales & Expenses'!$A$2:$A$495,"<"&EDATE(DATE($B$3,3,1),1)) -> 0 | E8: =B8-C8-D8 -> 0 | F8: =Settings!$B$3+Settings!$B$4+SUMIFS('Daily Sales & Expenses'!$D$2:$D$495,'Daily Sales & Expenses'!$A$2:$A$495,"<"&EDATE(DATE($B$3,3,1),1))-SUMIFS('Daily Sales & Expenses'!$J$2:$J$495,'Daily Sales & Expenses'!$A$2:$A$495,"<"&EDATE(DATE($B$3,3,1),1))-SUMIFS('Daily Sales & Expenses'!$K$2:$K$495,'Daily Sales & Expenses'!$A$2:$A$495,"<"&EDATE(DATE($B$3,3,1),1))-SUMIFS('Weekly Purchases'!$N$2:$N$503,'Weekly Purchases'!$B$2:$B$503,"<"&EDATE(DATE($B$3,3,1),1),'Weekly Purchases'!$B$2:$B$503,"<>")-SUMIFS('Weekly Purchases'!$N$2:$N$503,'Weekly Purchases'!$B$2:$B$503,"",'Weekly Purchases'!$A$2:$A$503,"<"&EDATE(DATE($B$3,3,1),1))-SUMIFS('Weekly Purchases'!$O$2:$O$503,'Weekly Purchases'!$B$2:$B$503,"<"&EDATE(DATE($B$3,3,1),1),'Weekly Purchases'!$B$2:$B$503,"<>")-SUMIFS('Weekly Purchases'!$O$2:$O$503,'Weekly Purchases'!$B$2:$B$503,"",'Weekly Purchases'!$A$2:$A$503,"<"&EDATE(DATE($B$3,3,1),1)) -> 0
A9: April | B9: =SUMIFS('Daily Sales & Expenses'!$D$2:$D$495,'Daily Sales & Expenses'!$A$2:$A$495,">="&DATE($B$3,4,1),'Daily Sales & Expenses'!$A$2:$A$495,"<"&EDATE(DATE($B$3,4,1),1)) -> 0 | C9: =SUMIFS('Weekly Purchases'!$M$2:$M$503,'Weekly Purchases'!$A$2:$A$503,">="&DATE($B$3,4,1),'Weekly Purchases'!$A$2:$A$503,"<"&EDATE(DATE($B$3,4,1),1)) -> 0 | D9: =SUMIFS('Daily Sales & Expenses'!$I$2:$I$495,'Daily Sales & Expenses'!$A$2:$A$495,">="&DATE($B$3,4,1),'Daily Sales & Expenses'!$A$2:$A$495,"<"&EDATE(DATE($B$3,4,1),1)) -> 0 | E9: =B9-C9-D9 -> 0 | F9: =Settings!$B$3+Settings!$B$4+SUMIFS('Daily Sales & Expenses'!$D$2:$D$495,'Daily Sales & Expenses'!$A$2:$A$495,"<"&EDATE(DATE($B$3,4,1),1))-SUMIFS('Daily Sales & Expenses'!$J$2:$J$495,'Daily Sales & Expenses'!$A$2:$A$495,"<"&EDATE(DATE($B$3,4,1),1))-SUMIFS('Daily Sales & Expenses'!$K$2:$K$495,'Daily Sales & Expenses'!$A$2:$A$495,"<"&EDATE(DATE($B$3,4,1),1))-SUMIFS('Weekly Purchases'!$N$2:$N$503,'Weekly Purchases'!$B$2:$B$503,"<"&EDATE(DATE($B$3,4,1),1),'Weekly Purchases'!$B$2:$B$503,"<>")-SUMIFS('Weekly Purchases'!$N$2:$N$503,'Weekly Purchases'!$B$2:$B$503,"",'Weekly Purchases'!$A$2:$A$503,"<"&EDATE(DATE($B$3,4,1),1))-SUMIFS('Weekly Purchases'!$O$2:$O$503,'Weekly Purchases'!$B$2:$B$503,"<"&EDATE(DATE($B$3,4,1),1),'Weekly Purchases'!$B$2:$B$503,"<>")-SUMIFS('Weekly Purchases'!$O$2:$O$503,'Weekly Purchases'!$B$2:$B$503,"",'Weekly Purchases'!$A$2:$A$503,"<"&EDATE(DATE($B$3,4,1),1)) -> 0
A10: May | B10: =SUMIFS('Daily Sales & Expenses'!$D$2:$D$495,'Daily Sales & Expenses'!$A$2:$A$495,">="&DATE($B$3,5,1),'Daily Sales & Expenses'!$A$2:$A$495,"<"&EDATE(DATE($B$3,5,1),1)) -> 0 | C10: =SUMIFS('Weekly Purchases'!$M$2:$M$503,'Weekly Purchases'!$A$2:$A$503,">="&DATE($B$3,5,1),'Weekly Purchases'!$A$2:$A$503,"<"&EDATE(DATE($B$3,5,1),1)) -> 0 | D10: =SUMIFS('Daily Sales & Expenses'!$I$2:$I$495,'Daily Sales & Expenses'!$A$2:$A$495,">="&DATE($B$3,5,1),'Daily Sales & Expenses'!$A$2:$A$495,"<"&EDATE(DATE($B$3,5,1),1)) -> 0 | E10: =B10-C10-D10 -> 0 | F10: =Settings!$B$3+Settings!$B$4+SUMIFS('Daily Sales & Expenses'!$D$2:$D$495,'Daily Sales & Expenses'!$A$2:$A$495,"<"&EDATE(DATE($B$3,5,1),1))-SUMIFS('Daily Sales & Expenses'!$J$2:$J$495,'Daily Sales & Expenses'!$A$2:$A$495,"<"&EDATE(DATE($B$3,5,1),1))-SUMIFS('Daily Sales & Expenses'!$K$2:$K$495,'Daily Sales & Expenses'!$A$2:$A$495,"<"&EDATE(DATE($B$3,5,1),1))-SUMIFS('Weekly Purchases'!$N$2:$N$503,'Weekly Purchases'!$B$2:$B$503,"<"&EDATE(DATE($B$3,5,1),1),'Weekly Purchases'!$B$2:$B$503,"<>")-SUMIFS('Weekly Purchases'!$N$2:$N$503,'Weekly Purchases'!$B$2:$B$503,"",'Weekly Purchases'!$A$2:$A$503,"<"&EDATE(DATE($B$3,5,1),1))-SUMIFS('Weekly Purchases'!$O$2:$O$503,'Weekly Purchases'!$B$2:$B$503,"<"&EDATE(DATE($B$3,5,1),1),'Weekly Purchases'!$B$2:$B$503,"<>")-SUMIFS('Weekly Purchases'!$O$2:$O$503,'Weekly Purchases'!$B$2:$B$503,"",'Weekly Purchases'!$A$2:$A$503,"<"&EDATE(DATE($B$3,5,1),1)) -> 0
A11: June | B11: =SUMIFS('Daily Sales & Expenses'!$D$2:$D$495,'Daily Sales & Expenses'!$A$2:$A$495,">="&DATE($B$3,6,1),'Daily Sales & Expenses'!$A$2:$A$495,"<"&EDATE(DATE($B$3,6,1),1)) -> 0 | C11: =SUMIFS('Weekly Purchases'!$M$2:$M$503,'Weekly Purchases'!$A$2:$A$503,">="&DATE($B$3,6,1),'Weekly Purchases'!$A$2:$A$503,"<"&EDATE(DATE($B$3,6,1),1)) -> 0 | D11: =SUMIFS('Daily Sales & Expenses'!$I$2:$I$495,'Daily Sales & Expenses'!$A$2:$A$495,">="&DATE($B$3,6,1),'Daily Sales & Expenses'!$A$2:$A$495,"<"&EDATE(DATE($B$3,6,1),1)) -> 0 | E11: =B11-C11-D11 -> 0 | F11: =Settings!$B$3+Settings!$B$4+SUMIFS('Daily Sales & Expenses'!$D$2:$D$495,'Daily Sales & Expenses'!$A$2:$A$495,"<"&EDATE(DATE($B$3,6,1),1))-SUMIFS('Daily Sales & Expenses'!$J$2:$J$495,'Daily Sales & Expenses'!$A$2:$A$495,"<"&EDATE(DATE($B$3,6,1),1))-SUMIFS('Daily Sales & Expenses'!$K$2:$K$495,'Daily Sales & Expenses'!$A$2:$A$495,"<"&EDATE(DATE($B$3,6,1),1))-SUMIFS('Weekly Purchases'!$N$2:$N$503,'Weekly Purchases'!$B$2:$B$503,"<"&EDATE(DATE($B$3,6,1),1),'Weekly Purchases'!$B$2:$B$503,"<>")-SUMIFS('Weekly Purchases'!$N$2:$N$503,'Weekly Purchases'!$B$2:$B$503,"",'Weekly Purchases'!$A$2:$A$503,"<"&EDATE(DATE($B$3,6,1),1))-SUMIFS('Weekly Purchases'!$O$2:$O$503,'Weekly Purchases'!$B$2:$B$503,"<"&EDATE(DATE($B$3,6,1),1),'Weekly Purchases'!$B$2:$B$503,"<>")-SUMIFS('Weekly Purchases'!$O$2:$O$503,'Weekly Purchases'!$B$2:$B$503,"",'Weekly Purchases'!$A$2:$A$503,"<"&EDATE(DATE($B$3,6,1),1)) -> 0
A12: July | B12: =SUMIFS('Daily Sales & Expenses'!$D$2:$D$495,'Daily Sales & Expenses'!$A$2:$A$495,">="&DATE($B$3,7,1),'Daily Sales & Expenses'!$A$2:$A$495,"<"&EDATE(DATE($B$3,7,1),1)) -> 0 | C12: =SUMIFS('Weekly Purchases'!$M$2:$M$503,'Weekly Purchases'!$A$2:$A$503,">="&DATE($B$3,7,1),'Weekly Purchases'!$A$2:$A$503,"<"&EDATE(DATE($B$3,7,1),1)) -> 0 | D12: =SUMIFS('Daily Sales & Expenses'!$I$2:$I$495,'Daily Sales & Expenses'!$A$2:$A$495,">="&DATE($B$3,7,1),'Daily Sales & Expenses'!$A$2:$A$495,"<"&EDATE(DATE($B$3,7,1),1)) -> 0 | E12: =B12-C12-D12 -> 0 | F12: =Settings!$B$3+Settings!$B$4+SUMIFS('Daily Sales & Expenses'!$D$2:$D$495,'Daily Sales & Expenses'!$A$2:$A$495,"<"&EDATE(DATE($B$3,7,1),1))-SUMIFS('Daily Sales & Expenses'!$J$2:$J$495,'Daily Sales & Expenses'!$A$2:$A$495,"<"&EDATE(DATE($B$3,7,1),1))-SUMIFS('Daily Sales & Expenses'!$K$2:$K$495,'Daily Sales & Expenses'!$A$2:$A$495,"<"&EDATE(DATE($B$3,7,1),1))-SUMIFS('Weekly Purchases'!$N$2:$N$503,'Weekly Purchases'!$B$2:$B$503,"<"&EDATE(DATE($B$3,7,1),1),'Weekly Purchases'!$B$2:$B$503,"<>")-SUMIFS('Weekly Purchases'!$N$2:$N$503,'Weekly Purchases'!$B$2:$B$503,"",'Weekly Purchases'!$A$2:$A$503,"<"&EDATE(DATE($B$3,7,1),1))-SUMIFS('Weekly Purchases'!$O$2:$O$503,'Weekly Purchases'!$B$2:$B$503,"<"&EDATE(DATE($B$3,7,1),1),'Weekly Purchases'!$B$2:$B$503,"<>")-SUMIFS('Weekly Purchases'!$O$2:$O$503,'Weekly Purchases'!$B$2:$B$503,"",'Weekly Purchases'!$A$2:$A$503,"<"&EDATE(DATE($B$3,7,1),1)) -> 0
A13: August | B13: =SUMIFS('Daily Sales & Expenses'!$D$2:$D$495,'Daily Sales & Expenses'!$A$2:$A$495,">="&DATE($B$3,8,1),'Daily Sales & Expenses'!$A$2:$A$495,"<"&EDATE(DATE($B$3,8,1),1)) -> 0 | C13: =SUMIFS('Weekly Purchases'!$M$2:$M$503,'Weekly Purchases'!$A$2:$A$503,">="&DATE($B$3,8,1),'Weekly Purchases'!$A$2:$A$503,"<"&EDATE(DATE($B$3,8,1),1)) -> 0 | D13: =SUMIFS('Daily Sales & Expenses'!$I$2:$I$495,'Daily Sales & Expenses'!$A$2:$A$495,">="&DATE($B$3,8,1),'Daily Sales & Expenses'!$A$2:$A$495,"<"&EDATE(DATE($B$3,8,1),1)) -> 0 | E13: =B13-C13-D13 -> 0 | F13: =Settings!$B$3+Settings!$B$4+SUMIFS('Daily Sales & Expenses'!$D$2:$D$495,'Daily Sales & Expenses'!$A$2:$A$495,"<"&EDATE(DATE($B$3,8,1),1))-SUMIFS('Daily Sales & Expenses'!$J$2:$J$495,'Daily Sales & Expenses'!$A$2:$A$495,"<"&EDATE(DATE($B$3,8,1),1))-SUMIFS('Daily Sales & Expenses'!$K$2:$K$495,'Daily Sales & Expenses'!$A$2:$A$495,"<"&EDATE(DATE($B$3,8,1),1))-SUMIFS('Weekly Purchases'!$N$2:$N$503,'Weekly Purchases'!$B$2:$B$503,"<"&EDATE(DATE($B$3,8,1),1),'Weekly Purchases'!$B$2:$B$503,"<>")-SUMIFS('Weekly Purchases'!$N$2:$N$503,'Weekly Purchases'!$B$2:$B$503,"",'Weekly Purchases'!$A$2:$A$503,"<"&EDATE(DATE($B$3,8,1),1))-SUMIFS('Weekly Purchases'!$O$2:$O$503,'Weekly Purchases'!$B$2:$B$503,"<"&EDATE(DATE($B$3,8,1),1),'Weekly Purchases'!$B$2:$B$503,"<>")-SUMIFS('Weekly Purchases'!$O$2:$O$503,'Weekly Purchases'!$B$2:$B$503,"",'Weekly Purchases'!$A$2:$A$503,"<"&EDATE(DATE($B$3,8,1),1)) -> 0
A14: September | B14: =SUMIFS('Daily Sales & Expenses'!$D$2:$D$495,'Daily Sales & Expenses'!$A$2:$A$495,">="&DATE($B$3,9,1),'Daily Sales & Expenses'!$A$2:$A$495,"<"&EDATE(DATE($B$3,9,1),1)) -> 244854 | C14: =SUMIFS('Weekly Purchases'!$M$2:$M$503,'Weekly Purchases'!$A$2:$A$503,">="&DATE($B$3,9,1),'Weekly Purchases'!$A$2:$A$503,"<"&EDATE(DATE($B$3,9,1),1)) -> 193826 | D14: =SUMIFS('Daily Sales & Expenses'!$I$2:$I$495,'Daily Sales & Expenses'!$A$2:$A$495,">="&DATE($B$3,9,1),'Daily Sales & Expenses'!$A$2:$A$495,"<"&EDATE(DATE($B$3,9,1),1)) -> 23242 | E14: =B14-C14-D14 -> 27786 | F14: =Settings!$B$3+Settings!$B$4+SUMIFS('Daily Sales & Expenses'!$D$2:$D$495,'Daily Sales & Expenses'!$A$2:$A$495,"<"&EDATE(DATE($B$3,9,1),1))-SUMIFS('Daily Sales & Expenses'!$J$2:$J$495,'Daily Sales & Expenses'!$A$2:$A$495,"<"&EDATE(DATE($B$3,9,1),1))-SUMIFS('Daily Sales & Expenses'!$K$2:$K$495,'Daily Sales & Expenses'!$A$2:$A$495,"<"&EDATE(DATE($B$3,9,1),1))-SUMIFS('Weekly Purchases'!$N$2:$N$503,'Weekly Purchases'!$B$2:$B$503,"<"&EDATE(DATE($B$3,9,1),1),'Weekly Purchases'!$B$2:$B$503,"<>")-SUMIFS('Weekly Purchases'!$N$2:$N$503,'Weekly Purchases'!$B$2:$B$503,"",'Weekly Purchases'!$A$2:$A$503,"<"&EDATE(DATE($B$3,9,1),1))-SUMIFS('Weekly Purchases'!$O$2:$O$503,'Weekly Purchases'!$B$2:$B$503,"<"&EDATE(DATE($B$3,9,1),1),'Weekly Purchases'!$B$2:$B$503,"<>")-SUMIFS('Weekly Purchases'!$O$2:$O$503,'Weekly Purchases'!$B$2:$B$503,"",'Weekly Purchases'!$A$2:$A$503,"<"&EDATE(DATE($B$3,9,1),1)) -> 27786
A15: October | B15: =SUMIFS('Daily Sales & Expenses'!$D$2:$D$495,'Daily Sales & Expenses'!$A$2:$A$495,">="&DATE($B$3,10,1),'Daily Sales & Expenses'!$A$2:$A$495,"<"&EDATE(DATE($B$3,10,1),1)) -> 0 | C15: =SUMIFS('Weekly Purchases'!$M$2:$M$503,'Weekly Purchases'!$A$2:$A$503,">="&DATE($B$3,10,1),'Weekly Purchases'!$A$2:$A$503,"<"&EDATE(DATE($B$3,10,1),1)) -> 0 | D15: =SUMIFS('Daily Sales & Expenses'!$I$2:$I$495,'Daily Sales & Expenses'!$A$2:$A$495,">="&DATE($B$3,10,1),'Daily Sales & Expenses'!$A$2:$A$495,"<"&EDATE(DATE($B$3,10,1),1)) -> 0 | E15: =B15-C15-D15 -> 0 | F15: =Settings!$B$3+Settings!$B$4+SUMIFS('Daily Sales & Expenses'!$D$2:$D$495,'Daily Sales & Expenses'!$A$2:$A$495,"<"&EDATE(DATE($B$3,10,1),1))-SUMIFS('Daily Sales & Expenses'!$J$2:$J$495,'Daily Sales & Expenses'!$A$2:$A$495,"<"&EDATE(DATE($B$3,10,1),1))-SUMIFS('Daily Sales & Expenses'!$K$2:$K$495,'Daily Sales & Expenses'!$A$2:$A$495,"<"&EDATE(DATE($B$3,10,1),1))-SUMIFS('Weekly Purchases'!$N$2:$N$503,'Weekly Purchases'!$B$2:$B$503,"<"&EDATE(DATE($B$3,10,1),1),'Weekly Purchases'!$B$2:$B$503,"<>")-SUMIFS('Weekly Purchases'!$N$2:$N$503,'Weekly Purchases'!$B$2:$B$503,"",'Weekly Purchases'!$A$2:$A$503,"<"&EDATE(DATE($B$3,10,1),1))-SUMIFS('Weekly Purchases'!$O$2:$O$503,'Weekly Purchases'!$B$2:$B$503,"<"&EDATE(DATE($B$3,10,1),1),'Weekly Purchases'!$B$2:$B$503,"<>")-SUMIFS('Weekly Purchases'!$O$2:$O$503,'Weekly Purchases'!$B$2:$B$503,"",'Weekly Purchases'!$A$2:$A$503,"<"&EDATE(DATE($B$3,10,1),1)) -> 27786
A16: November | B16: =SUMIFS('Daily Sales & Expenses'!$D$2:$D$495,'Daily Sales & Expenses'!$A$2:$A$495,">="&DATE($B$3,11,1),'Daily Sales & Expenses'!$A$2:$A$495,"<"&EDATE(DATE($B$3,11,1),1)) -> 0 | C16: =SUMIFS('Weekly Purchases'!$M$2:$M$503,'Weekly Purchases'!$A$2:$A$503,">="&DATE($B$3,11,1),'Weekly Purchases'!$A$2:$A$503,"<"&EDATE(DATE($B$3,11,1),1)) -> 0 | D16: =SUMIFS('Daily Sales & Expenses'!$I$2:$I$495,'Daily Sales & Expenses'!$A$2:$A$495,">="&DATE($B$3,11,1),'Daily Sales & Expenses'!$A$2:$A$495,"<"&EDATE(DATE($B$3,11,1),1)) -> 0 | E16: =B16-C16-D16 -> 0 | F16: =Settings!$B$3+Settings!$B$4+SUMIFS('Daily Sales & Expenses'!$D$2:$D$495,'Daily Sales & Expenses'!$A$2:$A$495,"<"&EDATE(DATE($B$3,11,1),1))-SUMIFS('Daily Sales & Expenses'!$J$2:$J$495,'Daily Sales & Expenses'!$A$2:$A$495,"<"&EDATE(DATE($B$3,11,1),1))-SUMIFS('Daily Sales & Expenses'!$K$2:$K$495,'Daily Sales & Expenses'!$A$2:$A$495,"<"&EDATE(DATE($B$3,11,1),1))-SUMIFS('Weekly Purchases'!$N$2:$N$503,'Weekly Purchases'!$B$2:$B$503,"<"&EDATE(DATE($B$3,11,1),1),'Weekly Purchases'!$B$2:$B$503,"<>")-SUMIFS('Weekly Purchases'!$N$2:$N$503,'Weekly Purchases'!$B$2:$B$503,"",'Weekly Purchases'!$A$2:$A$503,"<"&EDATE(DATE($B$3,11,1),1))-SUMIFS('Weekly Purchases'!$O$2:$O$503,'Weekly Purchases'!$B$2:$B$503,"<"&EDATE(DATE($B$3,11,1),1),'Weekly Purchases'!$B$2:$B$503,"<>")-SUMIFS('Weekly Purchases'!$O$2:$O$503,'Weekly Purchases'!$B$2:$B$503,"",'Weekly Purchases'!$A$2:$A$503,"<"&EDATE(DATE($B$3,11,1),1)) -> 27786
A17: December | B17: =SUMIFS('Daily Sales & Expenses'!$D$2:$D$495,'Daily Sales & Expenses'!$A$2:$A$495,">="&DATE($B$3,12,1),'Daily Sales & Expenses'!$A$2:$A$495,"<"&EDATE(DATE($B$3,12,1),1)) -> 0 | C17: =SUMIFS('Weekly Purchases'!$M$2:$M$503,'Weekly Purchases'!$A$2:$A$503,">="&DATE($B$3,12,1),'Weekly Purchases'!$A$2:$A$503,"<"&EDATE(DATE($B$3,12,1),1)) -> 0 | D17: =SUMIFS('Daily Sales & Expenses'!$I$2:$I$495,'Daily Sales & Expenses'!$A$2:$A$495,">="&DATE($B$3,12,1),'Daily Sales & Expenses'!$A$2:$A$495,"<"&EDATE(DATE($B$3,12,1),1)) -> 0 | E17: =B17-C17-D17 -> 0 | F17: =Settings!$B$3+Settings!$B$4+SUMIFS('Daily Sales & Expenses'!$D$2:$D$495,'Daily Sales & Expenses'!$A$2:$A$495,"<"&EDATE(DATE($B$3,12,1),1))-SUMIFS('Daily Sales & Expenses'!$J$2:$J$495,'Daily Sales & Expenses'!$A$2:$A$495,"<"&EDATE(DATE($B$3,12,1),1))-SUMIFS('Daily Sales & Expenses'!$K$2:$K$495,'Daily Sales & Expenses'!$A$2:$A$495,"<"&EDATE(DATE($B$3,12,1),1))-SUMIFS('Weekly Purchases'!$N$2:$N$503,'Weekly Purchases'!$B$2:$B$503,"<"&EDATE(DATE($B$3,12,1),1),'Weekly Purchases'!$B$2:$B$503,"<>")-SUMIFS('Weekly Purchases'!$N$2:$N$503,'Weekly Purchases'!$B$2:$B$503,"",'Weekly Purchases'!$A$2:$A$503,"<"&EDATE(DATE($B$3,12,1),1))-SUMIFS('Weekly Purchases'!$O$2:$O$503,'Weekly Purchases'!$B$2:$B$503,"<"&EDATE(DATE($B$3,12,1),1),'Weekly Purchases'!$B$2:$B$503,"<>")-SUMIFS('Weekly Purchases'!$O$2:$O$503,'Weekly Purchases'!$B$2:$B$503,"",'Weekly Purchases'!$A$2:$A$503,"<"&EDATE(DATE($B$3,12,1),1)) -> 27786
A18: YEAR TOTAL | B18: =SUM(B6:B17) -> 244854 | C18: =SUM(C6:C17) -> 193826 | D18: =SUM(D6:D17) -> 23242 | E18: =SUM(E6:E17) -> 27786 | F18: =F17 -> 27786

Sheet Daily Sales & Expenses
A1: Date | B1: Online Sales | C1: Cash Sales | D1: Total Sales | E1: =Settings!C7 -> Police | F1: =Settings!C8 -> Shop | G1: =Settings!C9 -> Transport | H1: =Settings!C10 -> Other | I1: Total Expenses | J1: Expense Paid Online | K1: Expense Paid Cash | L1: Online Balance | M1: Cash Balance | N1: Total Balance | O1: Daily Net Amount | P1: Notes
A2: 46271 | B2: 25458 | C2: 500 | D2: =IF($A2="","",SUM($B2:$C2)) -> 25958 | E2: 800 | F2: 48 | G2: 0 | H2: 0 | I2: =IF($A2="","",SUM($E2:$H2)) -> 848 | J2: 848 | K2: 0 | L2: =IF($A2="","",Settings!$B$3+SUMIFS($B$2:$B$495,$A$2:$A$495,"<="&$A2)-SUMIFS($J$2:$J$495,$A$2:$A$495,"<="&$A2)-SUMIFS('Weekly Purchases'!$N$2:$N$503,'Weekly Purchases'!$B$2:$B$503,"<>",'Weekly Purchases'!$B$2:$B$503,"<="&$A2)-SUMIFS('Weekly Purchases'!$N$2:$N$503,'Weekly Purchases'!$B$2:$B$503,"",'Weekly Purchases'!$A$2:$A$503,"<="&$A2)) -> 24610 | M2: =IF($A2="","",Settings!$B$4+SUMIFS($C$2:$C$495,$A$2:$A$495,"<="&$A2)-SUMIFS($K$2:$K$495,$A$2:$A$495,"<="&$A2)-SUMIFS('Weekly Purchases'!$O$2:$O$503,'Weekly Purchases'!$B$2:$B$503,"<>",'Weekly Purchases'!$B$2:$B$503,"<="&$A2)-SUMIFS('Weekly Purchases'!$O$2:$O$503,'Weekly Purchases'!$B$2:$B$503,"",'Weekly Purchases'!$A$2:$A$503,"<="&$A2)) -> 500 | N2: =IF($A2="","",L2+M2) -> 25110 | O2: =IF($A2="","",D2-I2) -> 25110
A3: 46272 | B3: 10490 | C3: 500 | D3: =IF($A3="","",SUM($B3:$C3)) -> 10990 | E3: 800 | F3: 48 | G3: 0 | H3: 0 | I3: =IF($A3="","",SUM($E3:$H3)) -> 848 | J3: 848 | K3: 0 | L3: =IF($A3="","",Settings!$B$3+SUMIFS($B$2:$B$495,$A$2:$A$495,"<="&$A3)-SUMIFS($J$2:$J$495,$A$2:$A$495,"<="&$A3)-SUMIFS('Weekly Purchases'!$N$2:$N$503,'Weekly Purchases'!$B$2:$B$503,"<>",'Weekly Purchases'!$B$2:$B$503,"<="&$A3)-SUMIFS('Weekly Purchases'!$N$2:$N$503,'Weekly Purchases'!$B$2:$B$503,"",'Weekly Purchases'!$A$2:$A$503,"<="&$A3)) -> 34252 | M3: =IF($A3="","",Settings!$B$4+SUMIFS($C$2:$C$495,$A$2:$A$495,"<="&$A3)-SUMIFS($K$2:$K$495,$A$2:$A$495,"<="&$A3)-SUMIFS('Weekly Purchases'!$O$2:$O$503,'Weekly Purchases'!$B$2:$B$503,"<>",'Weekly Purchases'!$B$2:$B$503,"<="&$A3)-SUMIFS('Weekly Purchases'!$O$2:$O$503,'Weekly Purchases'!$B$2:$B$503,"",'Weekly Purchases'!$A$2:$A$503,"<="&$A3)) -> 1000 | N3: =IF($A3="","",L3+M3) -> 35252 | O3: =IF($A3="","",D3-I3) -> 10142
A4: 46273 | B4: 4359 | C4: 3500 | D4: =IF($A4="","",SUM($B4:$C4)) -> 7859 | E4: 800 | F4: 501 | G4: 0 | H4: 498 | I4: =IF($A4="","",SUM($E4:$H4)) -> 1799 | J4: 1799 | K4: 0 | L4: =IF($A4="","",Settings!$B$3+SUMIFS($B$2:$B$495,$A$2:$A$495,"<="&$A4)-SUMIFS($J$2:$J$495,$A$2:$A$495,"<="&$A4)-SUMIFS('Weekly Purchases'!$N$2:$N$503,'Weekly Purchases'!$B$2:$B$503,"<>",'Weekly Purchases'!$B$2:$B$503,"<="&$A4)-SUMIFS('Weekly Purchases'!$N$2:$N$503,'Weekly Purchases'!$B$2:$B$503,"",'Weekly Purchases'!$A$2:$A$503,"<="&$A4)) -> 36812 | M4: =IF($A4="","",Settings!$B$4+SUMIFS($C$2:$C$495,$A$2:$A$495,"<="&$A4)-SUMIFS($K$2:$K$495,$A$2:$A$495,"<="&$A4)-SUMIFS('Weekly Purchases'!$O$2:$O$503,'Weekly Purchases'!$B$2:$B$503,"<>",'Weekly Purchases'!$B$2:$B$503,"<="&$A4)-SUMIFS('Weekly Purchases'!$O$2:$O$503,'Weekly Purchases'!$B$2:$B$503,"",'Weekly Purchases'!$A$2:$A$503,"<="&$A4)) -> 4500 | N4: =IF($A4="","",L4+M4) -> 41312 | O4: =IF($A4="","",D4-I4) -> 6060
A5: 46274 | B5: 12138 | C5: 500 | D5: =IF($A5="","",SUM($B5:$C5)) -> 12638 | E5: 800 | F5: 48 | G5: 0 | H5: 0 | I5: =IF($A5="","",SUM($E5:$H5)) -> 848 | J5: 848 | L5: =IF($A5="","",Settings!$B$3+SUMIFS($B$2:$B$495,$A$2:$A$495,"<="&$A5)-SUMIFS($J$2:$J$495,$A$2:$A$495,"<="&$A5)-SUMIFS('Weekly Purchases'!$N$2:$N$503,'Weekly Purchases'!$B$2:$B$503,"<>",'Weekly Purchases'!$B$2:$B$503,"<="&$A5)-SUMIFS('Weekly Purchases'!$N$2:$N$503,'Weekly Purchases'!$B$2:$B$503,"",'Weekly Purchases'!$A$2:$A$503,"<="&$A5)) -> 48102 | M5: =IF($A5="","",Settings!$B$4+SUMIFS($C$2:$C$495,$A$2:$A$495,"<="&$A5)-SUMIFS($K$2:$K$495,$A$2:$A$495,"<="&$A5)-SUMIFS('Weekly Purchases'!$O$2:$O$503,'Weekly Purchases'!$B$2:$B$503,"<>",'Weekly Purchases'!$B$2:$B$503,"<="&$A5)-SUMIFS('Weekly Purchases'!$O$2:$O$503,'Weekly Purchases'!$B$2:$B$503,"",'Weekly Purchases'!$A$2:$A$503,"<="&$A5)) -> 5000 | N5: =IF($A5="","",L5+M5) -> 53102 | O5: =IF($A5="","",D5-I5) -> 11790
A6: 46275 | B6: 18992 | C6: 220 | D6: =IF($A6="","",SUM($B6:$C6)) -> 19212 | E6: 800 | F6: 48 | G6: 2000 | H6: 0 | I6: =IF($A6="","",SUM($E6:$H6)) -> 2848 | J6: 2848 | L6: =IF($A6="","",Settings!$B$3+SUMIFS($B$2:$B$495,$A$2:$A$495,"<="&$A6)-SUMIFS($J$2:$J$495,$A$2:$A$495,"<="&$A6)-SUMIFS('Weekly Purchases'!$N$2:$N$503,'Weekly Purchases'!$B$2:$B$503,"<>",'Weekly Purchases'!$B$2:$B$503,"<="&$A6)-SUMIFS('Weekly Purchases'!$N$2:$N$503,'Weekly Purchases'!$B$2:$B$503,"",'Weekly Purchases'!$A$2:$A$503,"<="&$A6)) -> 64246 | M6: =IF($A6="","",Settings!$B$4+SUMIFS($C$2:$C$495,$A$2:$A$495,"<="&$A6)-SUMIFS($K$2:$K$495,$A$2:$A$495,"<="&$A6)-SUMIFS('Weekly Purchases'!$O$2:$O$503,'Weekly Purchases'!$B$2:$B$503,"<>",'Weekly Purchases'!$B$2:$B$503,"<="&$A6)-SUMIFS('Weekly Purchases'!$O$2:$O$503,'Weekly Purchases'!$B$2:$B$503,"",'Weekly Purchases'!$A$2:$A$503,"<="&$A6)) -> 5220 | N6: =IF($A6="","",L6+M6) -> 69466 | O6: =IF($A6="","",D6-I6) -> 16364
A7: 46276 | B7: 14899 | C7: 2950 | D7: =IF($A7="","",SUM($B7:$C7)) -> 17849 | E7: 800 | F7: 48 | G7: 0 | H7: 1586 | I7: =IF($A7="","",SUM($E7:$H7)) -> 2434 | J7: 2434 | L7: =IF($A7="","",Settings!$B$3+SUMIFS($B$2:$B$495,$A$2:$A$495,"<="&$A7)-SUMIFS($J$2:$J$495,$A$2:$A$495,"<="&$A7)-SUMIFS('Weekly Purchases'!$N$2:$N$503,'Weekly Purchases'!$B$2:$B$503,"<>",'Weekly Purchases'!$B$2:$B$503,"<="&$A7)-SUMIFS('Weekly Purchases'!$N$2:$N$503,'Weekly Purchases'!$B$2:$B$503,"",'Weekly Purchases'!$A$2:$A$503,"<="&$A7)) -> 76711 | M7: =IF($A7="","",Settings!$B$4+SUMIFS($C$2:$C$495,$A$2:$A$495,"<="&$A7)-SUMIFS($K$2:$K$495,$A$2:$A$495,"<="&$A7)-SUMIFS('Weekly Purchases'!$O$2:$O$503,'Weekly Purchases'!$B$2:$B$503,"<>",'Weekly Purchases'!$B$2:$B$503,"<="&$A7)-SUMIFS('Weekly Purchases'!$O$2:$O$503,'Weekly Purchases'!$B$2:$B$503,"",'Weekly Purchases'!$A$2:$A$503,"<="&$A7)) -> 8170 | N7: =IF($A7="","",L7+M7) -> 84881 | O7: =IF($A7="","",D7-I7) -> 15415
A8: 46277 | B8: 33395 | C8: 1000 | D8: =IF($A8="","",SUM($B8:$C8)) -> 34395 | E8: 800 | F8: 52 | G8: 0 | H8: 0 | I8: =IF($A8="","",SUM($E8:$H8)) -> 852 | J8: 852 | L8: =IF($A8="","",Settings!$B$3+SUMIFS($B$2:$B$495,$A$2:$A$495,"<="&$A8)-SUMIFS($J$2:$J$495,$A$2:$A$495,"<="&$A8)-SUMIFS('Weekly Purchases'!$N$2:$N$503,'Weekly Purchases'!$B$2:$B$503,"<>",'Weekly Purchases'!$B$2:$B$503,"<="&$A8)-SUMIFS('Weekly Purchases'!$N$2:$N$503,'Weekly Purchases'!$B$2:$B$503,"",'Weekly Purchases'!$A$2:$A$503,"<="&$A8)) -> 109254 | M8: =IF($A8="","",Settings!$B$4+SUMIFS($C$2:$C$495,$A$2:$A$495,"<="&$A8)-SUMIFS($K$2:$K$495,$A$2:$A$495,"<="&$A8)-SUMIFS('Weekly Purchases'!$O$2:$O$503,'Weekly Purchases'!$B$2:$B$503,"<>",'Weekly Purchases'!$B$2:$B$503,"<="&$A8)-SUMIFS('Weekly Purchases'!$O$2:$O$503,'Weekly Purchases'!$B$2:$B$503,"",'Weekly Purchases'!$A$2:$A$503,"<="&$A8)) -> 9170 | N8: =IF($A8="","",L8+M8) -> 118424 | O8: =IF($A8="","",D8-I8) -> 33543
A9: 46278 | B9: 21809 | C9: 0 | D9: =IF($A9="","",SUM($B9:$C9)) -> 21809 | E9: 800 | F9: 0 | G9: 0 | H9: 0 | I9: =IF($A9="","",SUM($E9:$H9)) -> 800 | J9: 800 | L9: =IF($A9="","",Settings!$B$3+SUMIFS($B$2:$B$495,$A$2:$A$495,"<="&$A9)-SUMIFS($J$2:$J$495,$A$2:$A$495,"<="&$A9)-SUMIFS('Weekly Purchases'!$N$2:$N$503,'Weekly Purchases'!$B$2:$B$503,"<>",'Weekly Purchases'!$B$2:$B$503,"<="&$A9)-SUMIFS('Weekly Purchases'!$N$2:$N$503,'Weekly Purchases'!$B$2:$B$503,"",'Weekly Purchases'!$A$2:$A$503,"<="&$A9)) -> 130263 | M9: =IF($A9="","",Settings!$B$4+SUMIFS($C$2:$C$495,$A$2:$A$495,"<="&$A9)-SUMIFS($K$2:$K$495,$A$2:$A$495,"<="&$A9)-SUMIFS('Weekly Purchases'!$O$2:$O$503,'Weekly Purchases'!$B$2:$B$503,"<>",'Weekly Purchases'!$B$2:$B$503,"<="&$A9)-SUMIFS('Weekly Purchases'!$O$2:$O$503,'Weekly Purchases'!$B$2:$B$503,"",'Weekly Purchases'!$A$2:$A$503,"<="&$A9)) -> 9170 | N9: =IF($A9="","",L9+M9) -> 139433 | O9: =IF($A9="","",D9-I9) -> 21009
A10: 46279 | D10: =IF($A10="","",SUM($B10:$C10)) -> 0 | I10: =IF($A10="","",SUM($E10:$H10)) -> 0 | L10: =IF($A10="","",Settings!$B$3+SUMIFS($B$2:$B$495,$A$2:$A$495,"<="&$A10)-SUMIFS($J$2:$J$495,$A$2:$A$495,"<="&$A10)-SUMIFS('Weekly Purchases'!$N$2:$N$503,'Weekly Purchases'!$B$2:$B$503,"<>",'Weekly Purchases'!$B$2:$B$503,"<="&$A10)-SUMIFS('Weekly Purchases'!$N$2:$N$503,'Weekly Purchases'!$B$2:$B$503,"",'Weekly Purchases'!$A$2:$A$503,"<="&$A10)) -> 130263 | M10: =IF($A10="","",Settings!$B$4+SUMIFS($C$2:$C$495,$A$2:$A$495,"<="&$A10)-SUMIFS($K$2:$K$495,$A$2:$A$495,"<="&$A10)-SUMIFS('Weekly Purchases'!$O$2:$O$503,'Weekly Purchases'!$B$2:$B$503,"<>",'Weekly Purchases'!$B$2:$B$503,"<="&$A10)-SUMIFS('Weekly Purchases'!$O$2:$O$503,'Weekly Purchases'!$B$2:$B$503,"",'Weekly Purchases'!$A$2:$A$503,"<="&$A10)) -> 9170 | N10: =IF($A10="","",L10+M10) -> 139433 | O10: =IF($A10="","",D10-I10) -> 0
A11: 46280 | D11: =IF($A11="","",SUM($B11:$C11)) -> 0 | I11: =IF($A11="","",SUM($E11:$H11)) -> 0 | L11: =IF($A11="","",Settings!$B$3+SUMIFS($B$2:$B$495,$A$2:$A$495,"<="&$A11)-SUMIFS($J$2:$J$495,$A$2:$A$495,"<="&$A11)-SUMIFS('Weekly Purchases'!$N$2:$N$503,'Weekly Purchases'!$B$2:$B$503,"<>",'Weekly Purchases'!$B$2:$B$503,"<="&$A11)-SUMIFS('Weekly Purchases'!$N$2:$N$503,'Weekly Purchases'!$B$2:$B$503,"",'Weekly Purchases'!$A$2:$A$503,"<="&$A11)) -> 130263 | M11: =IF($A11="","",Settings!$B$4+SUMIFS($C$2:$C$495,$A$2:$A$495,"<="&$A11)-SUMIFS($K$2:$K$495,$A$2:$A$495,"<="&$A11)-SUMIFS('Weekly Purchases'!$O$2:$O$503,'Weekly Purchases'!$B$2:$B$503,"<>",'Weekly Purchases'!$B$2:$B$503,"<="&$A11)-SUMIFS('Weekly Purchases'!$O$2:$O$503,'Weekly Purchases'!$B$2:$B$503,"",'Weekly Purchases'!$A$2:$A$503,"<="&$A11)) -> 9170 | N11: =IF($A11="","",L11+M11) -> 139433 | O11: =IF($A11="","",D11-I11) -> 0
A12: 46281 | D12: =IF($A12="","",SUM($B12:$C12)) -> 0 | I12: =IF($A12="","",SUM($E12:$H12)) -> 0 | L12: =IF($A12="","",Settings!$B$3+SUMIFS($B$2:$B$495,$A$2:$A$495,"<="&$A12)-SUMIFS($J$2:$J$495,$A$2:$A$495,"<="&$A12)-SUMIFS('Weekly Purchases'!$N$2:$N$503,'Weekly Purchases'!$B$2:$B$503,"<>",'Weekly Purchases'!$B$2:$B$503,"<="&$A12)-SUMIFS('Weekly Purchases'!$N$2:$N$503,'Weekly Purchases'!$B$2:$B$503,"",'Weekly Purchases'!$A$2:$A$503,"<="&$A12)) -> 130263 | M12: =IF($A12="","",Settings!$B$4+SUMIFS($C$2:$C$495,$A$2:$A$495,"<="&$A12)-SUMIFS($K$2:$K$495,$A$2:$A$495,"<="&$A12)-SUMIFS('Weekly Purchases'!$O$2:$O$503,'Weekly Purchases'!$B$2:$B$503,"<>",'Weekly Purchases'!$B$2:$B$503,"<="&$A12)-SUMIFS('Weekly Purchases'!$O$2:$O$503,'Weekly Purchases'!$B$2:$B$503,"",'Weekly Purchases'!$A$2:$A$503,"<="&$A12)) -> 9170 | N12: =IF($A12="","",L12+M12) -> 139433 | O12: =IF($A12="","",D12-I12) -> 0
A13: 46282 | D13: =IF($A13="","",SUM($B13:$C13)) -> 0 | I13: =IF($A13="","",SUM($E13:$H13)) -> 0 | L13: =IF($A13="","",Settings!$B$3+SUMIFS($B$2:$B$495,$A$2:$A$495,"<="&$A13)-SUMIFS($J$2:$J$495,$A$2:$A$495,"<="&$A13)-SUMIFS('Weekly Purchases'!$N$2:$N$503,'Weekly Purchases'!$B$2:$B$503,"<>",'Weekly Purchases'!$B$2:$B$503,"<="&$A13)-SUMIFS('Weekly Purchases'!$N$2:$N$503,'Weekly Purchases'!$B$2:$B$503,"",'Weekly Purchases'!$A$2:$A$503,"<="&$A13)) -> 130263 | M13: =IF($A13="","",Settings!$B$4+SUMIFS($C$2:$C$495,$A$2:$A$495,"<="&$A13)-SUMIFS($K$2:$K$495,$A$2:$A$495,"<="&$A13)-SUMIFS('Weekly Purchases'!$O$2:$O$503,'Weekly Purchases'!$B$2:$B$503,"<>",'Weekly Purchases'!$B$2:$B$503,"<="&$A13)-SUMIFS('Weekly Purchases'!$O$2:$O$503,'Weekly Purchases'!$B$2:$B$503,"",'Weekly Purchases'!$A$2:$A$503,"<="&$A13)) -> 9170 | N13: =IF($A13="","",L13+M13) -> 139433 | O13: =IF($A13="","",D13-I13) -> 0
A14: 46283 | B14: 9420 | C14: 5400 | D14: =IF($A14="","",SUM($B14:$C14)) -> 14820 | E14: 800 | F14: 0 | G14: 0 | H14: 0 | I14: =IF($A14="","",SUM($E14:$H14)) -> 800 | J14: 800 | L14: =IF($A14="","",Settings!$B$3+SUMIFS($B$2:$B$495,$A$2:$A$495,"<="&$A14)-SUMIFS($J$2:$J$495,$A$2:$A$495,"<="&$A14)-SUMIFS('Weekly Purchases'!$N$2:$N$503,'Weekly Purchases'!$B$2:$B$503,"<>",'Weekly Purchases'!$B$2:$B$503,"<="&$A14)-SUMIFS('Weekly Purchases'!$N$2:$N$503,'Weekly Purchases'!$B$2:$B$503,"",'Weekly Purchases'!$A$2:$A$503,"<="&$A14)) -> 138883 | M14: =IF($A14="","",Settings!$B$4+SUMIFS($C$2:$C$495,$A$2:$A$495,"<="&$A14)-SUMIFS($K$2:$K$495,$A$2:$A$495,"<="&$A14)-SUMIFS('Weekly Purchases'!$O$2:$O$503,'Weekly Purchases'!$B$2:$B$503,"<>",'Weekly Purchases'!$B$2:$B$503,"<="&$A14)-SUMIFS('Weekly Purchases'!$O$2:$O$503,'Weekly Purchases'!$B$2:$B$503,"",'Weekly Purchases'!$A$2:$A$503,"<="&$A14)) -> 14570 | N14: =IF($A14="","",L14+M14) -> 153453 | O14: =IF($A14="","",D14-I14) -> 14020
A15: 46284 | B15: 22529 | C15: 2000 | D15: =IF($A15="","",SUM($B15:$C15)) -> 24529 | E15: 800 | H15: 500 | I15: =IF($A15="","",SUM($E15:$H15)) -> 1300 | J15: 1300 | L15: =IF($A15="","",Settings!$B$3+SUMIFS($B$2:$B$495,$A$2:$A$495,"<="&$A15)-SUMIFS($J$2:$J$495,$A$2:$A$495,"<="&$A15)-SUMIFS('Weekly Purchases'!$N$2:$N$503,'Weekly Purchases'!$B$2:$B$503,"<>",'Weekly Purchases'!$B$2:$B$503,"<="&$A15)-SUMIFS('Weekly Purchases'!$N$2:$N$503,'Weekly Purchases'!$B$2:$B$503,"",'Weekly Purchases'!$A$2:$A$503,"<="&$A15)) -> 160112 | M15: =IF($A15="","",Settings!$B$4+SUMIFS($C$2:$C$495,$A$2:$A$495,"<="&$A15)-SUMIFS($K$2:$K$495,$A$2:$A$495,"<="&$A15)-SUMIFS('Weekly Purchases'!$O$2:$O$503,'Weekly Purchases'!$B$2:$B$503,"<>",'Weekly Purchases'!$B$2:$B$503,"<="&$A15)-SUMIFS('Weekly Purchases'!$O$2:$O$503,'Weekly Purchases'!$B$2:$B$503,"",'Weekly Purchases'!$A$2:$A$503,"<="&$A15)) -> 16570 | N15: =IF($A15="","",L15+M15) -> 176682 | O15: =IF($A15="","",D15-I15) -> 23229
A16: 46285 | B16: 14726 | C16: 1000 | D16: =IF($A16="","",SUM($B16:$C16)) -> 15726 | E16: 800 | F16: 52 | G16: 0 | H16: 1771 | I16: =IF($A16="","",SUM($E16:$H16)) -> 2623 | J16: 2623 | L16: =IF($A16="","",Settings!$B$3+SUMIFS($B$2:$B$495,$A$2:$A$495,"<="&$A16)-SUMIFS($J$2:$J$495,$A$2:$A$495,"<="&$A16)-SUMIFS('Weekly Purchases'!$N$2:$N$503,'Weekly Purchases'!$B$2:$B$503,"<>",'Weekly Purchases'!$B$2:$B$503,"<="&$A16)-SUMIFS('Weekly Purchases'!$N$2:$N$503,'Weekly Purchases'!$B$2:$B$503,"",'Weekly Purchases'!$A$2:$A$503,"<="&$A16)) -> 172215 | M16: =IF($A16="","",Settings!$B$4+SUMIFS($C$2:$C$495,$A$2:$A$495,"<="&$A16)-SUMIFS($K$2:$K$495,$A$2:$A$495,"<="&$A16)-SUMIFS('Weekly Purchases'!$O$2:$O$503,'Weekly Purchases'!$B$2:$B$503,"<>",'Weekly Purchases'!$B$2:$B$503,"<="&$A16)-SUMIFS('Weekly Purchases'!$O$2:$O$503,'Weekly Purchases'!$B$2:$B$503,"",'Weekly Purchases'!$A$2:$A$503,"<="&$A16)) -> 17570 | N16: =IF($A16="","",L16+M16) -> 189785 | O16: =IF($A16="","",D16-I16) -> 13103
A17: 46286 | D17: =IF($A17="","",SUM($B17:$C17)) -> 0 | I17: =IF($A17="","",SUM($E17:$H17)) -> 0 | L17: =IF($A17="","",Settings!$B$3+SUMIFS($B$2:$B$495,$A$2:$A$495,"<="&$A17)-SUMIFS($J$2:$J$495,$A$2:$A$495,"<="&$A17)-SUMIFS('Weekly Purchases'!$N$2:$N$503,'Weekly Purchases'!$B$2:$B$503,"<>",'Weekly Purchases'!$B$2:$B$503,"<="&$A17)-SUMIFS('Weekly Purchases'!$N$2:$N$503,'Weekly Purchases'!$B$2:$B$503,"",'Weekly Purchases'!$A$2:$A$503,"<="&$A17)) -> 172215 | M17: =IF($A17="","",Settings!$B$4+SUMIFS($C$2:$C$495,$A$2:$A$495,"<="&$A17)-SUMIFS($K$2:$K$495,$A$2:$A$495,"<="&$A17)-SUMIFS('Weekly Purchases'!$O$2:$O$503,'Weekly Purchases'!$B$2:$B$503,"<>",'Weekly Purchases'!$B$2:$B$503,"<="&$A17)-SUMIFS('Weekly Purchases'!$O$2:$O$503,'Weekly Purchases'!$B$2:$B$503,"",'Weekly Purchases'!$A$2:$A$503,"<="&$A17)) -> 17570 | N17: =IF($A17="","",L17+M17) -> 189785 | O17: =IF($A17="","",D17-I17) -> 0
A18: 46287 | B18: 18110 | C18: 0 | D18: =IF($A18="","",SUM($B18:$C18)) -> 18110 | E18: 800 | F18: 52 | G18: 0 | H18: 0 | I18: =IF($A18="","",SUM($E18:$H18)) -> 852 | J18: 852 | K18: 0 | L18: =IF($A18="","",Settings!$B$3+SUMIFS($B$2:$B$495,$A$2:$A$495,"<="&$A18)-SUMIFS($J$2:$J$495,$A$2:$A$495,"<="&$A18)-SUMIFS('Weekly Purchases'!$N$2:$N$503,'Weekly Purchases'!$B$2:$B$503,"<>",'Weekly Purchases'!$B$2:$B$503,"<="&$A18)-SUMIFS('Weekly Purchases'!$N$2:$N$503,'Weekly Purchases'!$B$2:$B$503,"",'Weekly Purchases'!$A$2:$A$503,"<="&$A18)) -> 189473 | M18: =IF($A18="","",Settings!$B$4+SUMIFS($C$2:$C$495,$A$2:$A$495,"<="&$A18)-SUMIFS($K$2:$K$495,$A$2:$A$495,"<="&$A18)-SUMIFS('Weekly Purchases'!$O$2:$O$503,'Weekly Purchases'!$B$2:$B$503,"<>",'Weekly Purchases'!$B$2:$B$503,"<="&$A18)-SUMIFS('Weekly Purchases'!$O$2:$O$503,'Weekly Purchases'!$B$2:$B$503,"",'Weekly Purchases'!$A$2:$A$503,"<="&$A18)) -> 17570 | N18: =IF($A18="","",L18+M18) -> 207043 | O18: =IF($A18="","",D18-I18) -> 17258
A19: 46288 | B19: 14560 | C19: 0 | D19: =IF($A19="","",SUM($B19:$C19)) -> 14560 | E19: 800 | F19: 20 | G19: 475 | H19: 0 | I19: =IF($A19="","",SUM($E19:$H19)) -> 1295 | J19: 1295 | K19: 0 | L19: =IF($A19="","",Settings!$B$3+SUMIFS($B$2:$B$495,$A$2:$A$495,"<="&$A19)-SUMIFS($J$2:$J$495,$A$2:$A$495,"<="&$A19)-SUMIFS('Weekly Purchases'!$N$2:$N$503,'Weekly Purchases'!$B$2:$B$503,"<>",'Weekly Purchases'!$B$2:$B$503,"<="&$A19)-SUMIFS('Weekly Purchases'!$N$2:$N$503,'Weekly Purchases'!$B$2:$B$503,"",'Weekly Purchases'!$A$2:$A$503,"<="&$A19)) -> 202738 | M19: =IF($A19="","",Settings!$B$4+SUMIFS($C$2:$C$495,$A$2:$A$495,"<="&$A19)-SUMIFS($K$2:$K$495,$A$2:$A$495,"<="&$A19)-SUMIFS('Weekly Purchases'!$O$2:$O$503,'Weekly Purchases'!$B$2:$B$503,"<>",'Weekly Purchases'!$B$2:$B$503,"<="&$A19)-SUMIFS('Weekly Purchases'!$O$2:$O$503,'Weekly Purchases'!$B$2:$B$503,"",'Weekly Purchases'!$A$2:$A$503,"<="&$A19)) -> 17570 | N19: =IF($A19="","",L19+M19) -> 220308 | O19: =IF($A19="","",D19-I19) -> 13265
A20: 46289 | B20: 5399 | C20: 1000 | D20: =IF($A20="","",SUM($B20:$C20)) -> 6399 | E20: 800 | F20: 2032 | G20: 2000 | H20: 263 | I20: =IF($A20="","",SUM($E20:$H20)) -> 5095 | J20: 5095 | K20: 0 | L20: =IF($A20="","",Settings!$B$3+SUMIFS($B$2:$B$495,$A$2:$A$495,"<="&$A20)-SUMIFS($J$2:$J$495,$A$2:$A$495,"<="&$A20)-SUMIFS('Weekly Purchases'!$N$2:$N$503,'Weekly Purchases'!$B$2:$B$503,"<>",'Weekly Purchases'!$B$2:$B$503,"<="&$A20)-SUMIFS('Weekly Purchases'!$N$2:$N$503,'Weekly Purchases'!$B$2:$B$503,"",'Weekly Purchases'!$A$2:$A$503,"<="&$A20)) -> 9216 | M20: =IF($A20="","",Settings!$B$4+SUMIFS($C$2:$C$495,$A$2:$A$495,"<="&$A20)-SUMIFS($K$2:$K$495,$A$2:$A$495,"<="&$A20)-SUMIFS('Weekly Purchases'!$O$2:$O$503,'Weekly Purchases'!$B$2:$B$503,"<>",'Weekly Purchases'!$B$2:$B$503,"<="&$A20)-SUMIFS('Weekly Purchases'!$O$2:$O$503,'Weekly Purchases'!$B$2:$B$503,"",'Weekly Purchases'!$A$2:$A$503,"<="&$A20)) -> 18570 | N20: =IF($A20="","",L20+M20) -> 27786 | O20: =IF($A20="","",D20-I20) -> 1304
D21: =IF($A21="","",SUM($B21:$C21)) | I21: =IF($A21="","",SUM($E21:$H21)) | L21: =IF($A21="","",Settings!$B$3+SUMIFS($B$2:$B$495,$A$2:$A$495,"<="&$A21)-SUMIFS($J$2:$J$495,$A$2:$A$495,"<="&$A21)-SUMIFS('Weekly Purchases'!$N$2:$N$503,'Weekly Purchases'!$B$2:$B$503,"<>",'Weekly Purchases'!$B$2:$B$503,"<="&$A21)-SUMIFS('Weekly Purchases'!$N$2:$N$503,'Weekly Purchases'!$B$2:$B$503,"",'Weekly Purchases'!$A$2:$A$503,"<="&$A21)) | M21: =IF($A21="","",Settings!$B$4+SUMIFS($C$2:$C$495,$A$2:$A$495,"<="&$A21)-SUMIFS($K$2:$K$495,$A$2:$A$495,"<="&$A21)-SUMIFS('Weekly Purchases'!$O$2:$O$503,'Weekly Purchases'!$B$2:$B$503,"<>",'Weekly Purchases'!$B$2:$B$503,"<="&$A21)-SUMIFS('Weekly Purchases'!$O$2:$O$503,'Weekly Purchases'!$B$2:$B$503,"",'Weekly Purchases'!$A$2:$A$503,"<="&$A21)) | N21: =IF($A21="","",L21+M21) | O21: =IF($A21="","",D21-I21)
D22: =IF($A22="","",SUM($B22:$C22)) | I22: =IF($A22="","",SUM($E22:$H22)) | L22: =IF($A22="","",Settings!$B$3+SUMIFS($B$2:$B$495,$A$2:$A$495,"<="&$A22)-SUMIFS($J$2:$J$495,$A$2:$A$495,"<="&$A22)-SUMIFS('Weekly Purchases'!$N$2:$N$503,'Weekly Purchases'!$B$2:$B$503,"<>",'Weekly Purchases'!$B$2:$B$503,"<="&$A22)-SUMIFS('Weekly Purchases'!$N$2:$N$503,'Weekly Purchases'!$B$2:$B$503,"",'Weekly Purchases'!$A$2:$A$503,"<="&$A22)) | M22: =IF($A22="","",Settings!$B$4+SUMIFS($C$2:$C$495,$A$2:$A$495,"<="&$A22)-SUMIFS($K$2:$K$495,$A$2:$A$495,"<="&$A22)-SUMIFS('Weekly Purchases'!$O$2:$O$503,'Weekly Purchases'!$B$2:$B$503,"<>",'Weekly Purchases'!$B$2:$B$503,"<="&$A22)-SUMIFS('Weekly Purchases'!$O$2:$O$503,'Weekly Purchases'!$B$2:$B$503,"",'Weekly Purchases'!$A$2:$A$503,"<="&$A22)) | N22: =IF($A22="","",L22+M22) | O22: =IF($A22="","",D22-I22)
D23: =IF($A23="","",SUM($B23:$C23)) | I23: =IF($A23="","",SUM($E23:$H23)) | L23: =IF($A23="","",Settings!$B$3+SUMIFS($B$2:$B$495,$A$2:$A$495,"<="&$A23)-SUMIFS($J$2:$J$495,$A$2:$A$495,"<="&$A23)-SUMIFS('Weekly Purchases'!$N$2:$N$503,'Weekly Purchases'!$B$2:$B$503,"<>",'Weekly Purchases'!$B$2:$B$503,"<="&$A23)-SUMIFS('Weekly Purchases'!$N$2:$N$503,'Weekly Purchases'!$B$2:$B$503,"",'Weekly Purchases'!$A$2:$A$503,"<="&$A23)) | M23: =IF($A23="","",Settings!$B$4+SUMIFS($C$2:$C$495,$A$2:$A$495,"<="&$A23)-SUMIFS($K$2:$K$495,$A$2:$A$495,"<="&$A23)-SUMIFS('Weekly Purchases'!$O$2:$O$503,'Weekly Purchases'!$B$2:$B$503,"<>",'Weekly Purchases'!$B$2:$B$503,"<="&$A23)-SUMIFS('Weekly Purchases'!$O$2:$O$503,'Weekly Purchases'!$B$2:$B$503,"",'Weekly Purchases'!$A$2:$A$503,"<="&$A23)) | N23: =IF($A23="","",L23+M23) | O23: =IF($A23="","",D23-I23)
D24: =IF($A24="","",SUM($B24:$C24)) | I24: =IF($A24="","",SUM($E24:$H24)) | L24: =IF($A24="","",Settings!$B$3+SUMIFS($B$2:$B$495,$A$2:$A$495,"<="&$A24)-SUMIFS($J$2:$J$495,$A$2:$A$495,"<="&$A24)-SUMIFS('Weekly Purchases'!$N$2:$N$503,'Weekly Purchases'!$B$2:$B$503,"<>",'Weekly Purchases'!$B$2:$B$503,"<="&$A24)-SUMIFS('Weekly Purchases'!$N$2:$N$503,'Weekly Purchases'!$B$2:$B$503,"",'Weekly Purchases'!$A$2:$A$503,"<="&$A24)) | M24: =IF($A24="","",Settings!$B$4+SUMIFS($C$2:$C$495,$A$2:$A$495,"<="&$A24)-SUMIFS($K$2:$K$495,$A$2:$A$495,"<="&$A24)-SUMIFS('Weekly Purchases'!$O$2:$O$503,'Weekly Purchases'!$B$2:$B$503,"<>",'Weekly Purchases'!$B$2:$B$503,"<="&$A24)-SUMIFS('Weekly Purchases'!$O$2:$O$503,'Weekly Purchases'!$B$2:$B$503,"",'Weekly Purchases'!$A$2:$A$503,"<="&$A24)) | N24: =IF($A24="","",L24+M24) | O24: =IF($A24="","",D24-I24)
D25: =IF($A25="","",SUM($B25:$C25)) | I25: =IF($A25="","",SUM($E25:$H25)) | L25: =IF($A25="","",Settings!$B$3+SUMIFS($B$2:$B$495,$A$2:$A$495,"<="&$A25)-SUMIFS($J$2:$J$495,$A$2:$A$495,"<="&$A25)-SUMIFS('Weekly Purchases'!$N$2:$N$503,'Weekly Purchases'!$B$2:$B$503,"<>",'Weekly Purchases'!$B$2:$B$503,"<="&$A25)-SUMIFS('Weekly Purchases'!$N$2:$N$503,'Weekly Purchases'!$B$2:$B$503,"",'Weekly Purchases'!$A$2:$A$503,"<="&$A25)) | M25: =IF($A25="","",Settings!$B$4+SUMIFS($C$2:$C$495,$A$2:$A$495,"<="&$A25)-SUMIFS($K$2:$K$495,$A$2:$A$495,"<="&$A25)-SUMIFS('Weekly Purchases'!$O$2:$O$503,'Weekly Purchases'!$B$2:$B$503,"<>",'Weekly Purchases'!$B$2:$B$503,"<="&$A25)-SUMIFS('Weekly Purchases'!$O$2:$O$503,'Weekly Purchases'!$B$2:$B$503,"",'Weekly Purchases'!$A$2:$A$503,"<="&$A25)) | N25: =IF($A25="","",L25+M25) | O25: =IF($A25="","",D25-I25)
D26: =IF($A26="","",SUM($B26:$C26)) | I26: =IF($A26="","",SUM($E26:$H26)) | L26: =IF($A26="","",Settings!$B$3+SUMIFS($B$2:$B$495,$A$2:$A$495,"<="&$A26)-SUMIFS($J$2:$J$495,$A$2:$A$495,"<="&$A26)-SUMIFS('Weekly Purchases'!$N$2:$N$503,'Weekly Purchases'!$B$2:$B$503,"<>",'Weekly Purchases'!$B$2:$B$503,"<="&$A26)-SUMIFS('Weekly Purchases'!$N$2:$N$503,'Weekly Purchases'!$B$2:$B$503,"",'Weekly Purchases'!$A$2:$A$503,"<="&$A26)) | M26: =IF($A26="","",Settings!$B$4+SUMIFS($C$2:$C$495,$A$2:$A$495,"<="&$A26)-SUMIFS($K$2:$K$495,$A$2:$A$495,"<="&$A26)-SUMIFS('Weekly Purchases'!$O$2:$O$503,'Weekly Purchases'!$B$2:$B$503,"<>",'Weekly Purchases'!$B$2:$B$503,"<="&$A26)-SUMIFS('Weekly Purchases'!$O$2:$O$503,'Weekly Purchases'!$B$2:$B$503,"",'Weekly Purchases'!$A$2:$A$503,"<="&$A26)) | N26: =IF($A26="","",L26+M26) | O26: =IF($A26="","",D26-I26)
D27: =IF($A27="","",SUM($B27:$C27)) | I27: =IF($A27="","",SUM($E27:$H27)) | L27: =IF($A27="","",Settings!$B$3+SUMIFS($B$2:$B$495,$A$2:$A$495,"<="&$A27)-SUMIFS($J$2:$J$495,$A$2:$A$495,"<="&$A27)-SUMIFS('Weekly Purchases'!$N$2:$N$503,'Weekly Purchases'!$B$2:$B$503,"<>",'Weekly Purchases'!$B$2:$B$503,"<="&$A27)-SUMIFS('Weekly Purchases'!$N$2:$N$503,'Weekly Purchases'!$B$2:$B$503,"",'Weekly Purchases'!$A$2:$A$503,"<="&$A27)) | M27: =IF($A27="","",Settings!$B$4+SUMIFS($C$2:$C$495,$A$2:$A$495,"<="&$A27)-SUMIFS($K$2:$K$495,$A$2:$A$495,"<="&$A27)-SUMIFS('Weekly Purchases'!$O$2:$O$503,'Weekly Purchases'!$B$2:$B$503,"<>",'Weekly Purchases'!$B$2:$B$503,"<="&$A27)-SUMIFS('Weekly Purchases'!$O$2:$O$503,'Weekly Purchases'!$B$2:$B$503,"",'Weekly Purchases'!$A$2:$A$503,"<="&$A27)) | N27: =IF($A27="","",L27+M27) | O27: =IF($A27="","",D27-I27)
D28: =IF($A28="","",SUM($B28:$C28)) | I28: =IF($A28="","",SUM($E28:$H28)) | L28: =IF($A28="","",Settings!$B$3+SUMIFS($B$2:$B$495,$A$2:$A$495,"<="&$A28)-SUMIFS($J$2:$J$495,$A$2:$A$495,"<="&$A28)-SUMIFS('Weekly Purchases'!$N$2:$N$503,'Weekly Purchases'!$B$2:$B$503,"<>",'Weekly Purchases'!$B$2:$B$503,"<="&$A28)-SUMIFS('Weekly Purchases'!$N$2:$N$503,'Weekly Purchases'!$B$2:$B$503,"",'Weekly Purchases'!$A$2:$A$503,"<="&$A28)) | M28: =IF($A28="","",Settings!$B$4+SUMIFS($C$2:$C$495,$A$2:$A$495,"<="&$A28)-SUMIFS($K$2:$K$495,$A$2:$A$495,"<="&$A28)-SUMIFS('Weekly Purchases'!$O$2:$O$503,'Weekly Purchases'!$B$2:$B$503,"<>",'Weekly Purchases'!$B$2:$B$503,"<="&$A28)-SUMIFS('Weekly Purchases'!$O$2:$O$503,'Weekly Purchases'!$B$2:$B$503,"",'Weekly Purchases'!$A$2:$A$503,"<="&$A28)) | N28: =IF($A28="","",L28+M28) | O28: =IF($A28="","",D28-I28)
D29: =IF($A29="","",SUM($B29:$C29)) | I29: =IF($A29="","",SUM($E29:$H29)) | L29: =IF($A29="","",Settings!$B$3+SUMIFS($B$2:$B$495,$A$2:$A$495,"<="&$A29)-SUMIFS($J$2:$J$495,$A$2:$A$495,"<="&$A29)-SUMIFS('Weekly Purchases'!$N$2:$N$503,'Weekly Purchases'!$B$2:$B$503,"<>",'Weekly Purchases'!$B$2:$B$503,"<="&$A29)-SUMIFS('Weekly Purchases'!$N$2:$N$503,'Weekly Purchases'!$B$2:$B$503,"",'Weekly Purchases'!$A$2:$A$503,"<="&$A29)) | M29: =IF($A29="","",Settings!$B$4+SUMIFS($C$2:$C$495,$A$2:$A$495,"<="&$A29)-SUMIFS($K$2:$K$495,$A$2:$A$495,"<="&$A29)-SUMIFS('Weekly Purchases'!$O$2:$O$503,'Weekly Purchases'!$B$2:$B$503,"<>",'Weekly Purchases'!$B$2:$B$503,"<="&$A29)-SUMIFS('Weekly Purchases'!$O$2:$O$503,'Weekly Purchases'!$B$2:$B$503,"",'Weekly Purchases'!$A$2:$A$503,"<="&$A29)) | N29: =IF($A29="","",L29+M29) | O29: =IF($A29="","",D29-I29)
D30: =IF($A30="","",SUM($B30:$C30)) | I30: =IF($A30="","",SUM($E30:$H30)) | L30: =IF($A30="","",Settings!$B$3+SUMIFS($B$2:$B$495,$A$2:$A$495,"<="&$A30)-SUMIFS($J$2:$J$495,$A$2:$A$495,"<="&$A30)-SUMIFS('Weekly Purchases'!$N$2:$N$503,'Weekly Purchases'!$B$2:$B$503,"<>",'Weekly Purchases'!$B$2:$B$503,"<="&$A30)-SUMIFS('Weekly Purchases'!$N$2:$N$503,'Weekly Purchases'!$B$2:$B$503,"",'Weekly Purchases'!$A$2:$A$503,"<="&$A30)) | M30: =IF($A30="","",Settings!$B$4+SUMIFS($C$2:$C$495,$A$2:$A$495,"<="&$A30)-SUMIFS($K$2:$K$495,$A$2:$A$495,"<="&$A30)-SUMIFS('Weekly Purchases'!$O$2:$O$503,'Weekly Purchases'!$B$2:$B$503,"<>",'Weekly Purchases'!$B$2:$B$503,"<="&$A30)-SUMIFS('Weekly Purchases'!$O$2:$O$503,'Weekly Purchases'!$B$2:$B$503,"",'Weekly Purchases'!$A$2:$A$503,"<="&$A30)) | N30: =IF($A30="","",L30+M30) | O30: =IF($A30="","",D30-I30)
D31: =IF($A31="","",SUM($B31:$C31)) | I31: =IF($A31="","",SUM($E31:$H31)) | L31: =IF($A31="","",Settings!$B$3+SUMIFS($B$2:$B$495,$A$2:$A$495,"<="&$A31)-SUMIFS($J$2:$J$495,$A$2:$A$495,"<="&$A31)-SUMIFS('Weekly Purchases'!$N$2:$N$503,'Weekly Purchases'!$B$2:$B$503,"<>",'Weekly Purchases'!$B$2:$B$503,"<="&$A31)-SUMIFS('Weekly Purchases'!$N$2:$N$503,'Weekly Purchases'!$B$2:$B$503,"",'Weekly Purchases'!$A$2:$A$503,"<="&$A31)) | M31: =IF($A31="","",Settings!$B$4+SUMIFS($C$2:$C$495,$A$2:$A$495,"<="&$A31)-SUMIFS($K$2:$K$495,$A$2:$A$495,"<="&$A31)-SUMIFS('Weekly Purchases'!$O$2:$O$503,'Weekly Purchases'!$B$2:$B$503,"<>",'Weekly Purchases'!$B$2:$B$503,"<="&$A31)-SUMIFS('Weekly Purchases'!$O$2:$O$503,'Weekly Purchases'!$B$2:$B$503,"",'Weekly Purchases'!$A$2:$A$503,"<="&$A31)) | N31: =IF($A31="","",L31+M31) | O31: =IF($A31="","",D31-I31)
D32: =IF($A32="","",SUM($B32:$C32)) | I32: =IF($A32="","",SUM($E32:$H32)) | L32: =IF($A32="","",Settings!$B$3+SUMIFS($B$2:$B$495,$A$2:$A$495,"<="&$A32)-SUMIFS($J$2:$J$495,$A$2:$A$495,"<="&$A32)-SUMIFS('Weekly Purchases'!$N$2:$N$503,'Weekly Purchases'!$B$2:$B$503,"<>",'Weekly Purchases'!$B$2:$B$503,"<="&$A32)-SUMIFS('Weekly Purchases'!$N$2:$N$503,'Weekly Purchases'!$B$2:$B$503,"",'Weekly Purchases'!$A$2:$A$503,"<="&$A32)) | M32: =IF($A32="","",Settings!$B$4+SUMIFS($C$2:$C$495,$A$2:$A$495,"<="&$A32)-SUMIFS($K$2:$K$495,$A$2:$A$495,"<="&$A32)-SUMIFS('Weekly Purchases'!$O$2:$O$503,'Weekly Purchases'!$B$2:$B$503,"<>",'Weekly Purchases'!$B$2:$B$503,"<="&$A32)-SUMIFS('Weekly Purchases'!$O$2:$O$503,'Weekly Purchases'!$B$2:$B$503,"",'Weekly Purchases'!$A$2:$A$503,"<="&$A32)) | N32: =IF($A32="","",L32+M32) | O32: =IF($A32="","",D32-I32)
... D495: =IF($A495="","",SUM($B495:$C495)) | I495: =IF($A495="","",SUM($E495:$H495)) | L495: =IF($A495="","",Settings!$B$3+SUMIFS($B$2:$B$495,$A$2:$A$495,"<="&$A495)-SUMIFS($J$2:$J$495,$A$2:$A$495,"<="&$A495)-SUMIFS('Weekly Purchases'!$N$2:$N$503,'Weekly Purchases'!$B$2:$B$503,"<>",'Weekly Purchases'!$B$2:$B$503,"<="&$A495)-SUMIFS('Weekly Purchases'!$N$2:$N$503,'Weekly Purchases'!$B$2:$B$503,"",'Weekly Purchases'!$A$2:$A$503,"<="&$A495)) | M495: =IF($A495="","",Settings!$B$4+SUMIFS($C$2:$C$495,$A$2:$A$495,"<="&$A495)-SUMIFS($K$2:$K$495,$A$2:$A$495,"<="&$A495)-SUMIFS('Weekly Purchases'!$O$2:$O$503,'Weekly Purchases'!$B$2:$B$503,"<>",'Weekly Purchases'!$B$2:$B$503,"<="&$A495)-SUMIFS('Weekly Purchases'!$O$2:$O$503,'Weekly Purchases'!$B$2:$B$503,"",'Weekly Purchases'!$A$2:$A$503,"<="&$A495)) | N495: =IF($A495="","",L495+M495) | O495: =IF($A495="","",D495-I495)

Sheet Weekly Purchases
A1: Purchase Date | B1: Payment Date | C1: =Settings!A7 -> RawDawg | D1: =Settings!A8 -> Fetch | E1: =Settings!A9 -> Nord | F1: =Settings!A10 -> Belucci | G1: =Settings!A11 -> FoolHardy | H1: =Settings!A12 -> Core | I1: =Settings!A13 -> Dexer | J1: =Settings!A14 -> Nordich | K1: =Settings!A15 -> Never | L1: =Settings!A16 -> Ozaro | M1: Total Weekly Purchase | N1: Online Purchase Paid | O1: Cash Purchase Paid | P1: Pending Purchase
A2: 46289 | B2: 46289 | C2: 64049 | D2: 95077 | E2: 0 | F2: 26500 | G2: 0 | H2: 0 | I2: 0 | J2: 0 | K2: 0 | L2: 8200 | M2: =IF($A2="","",SUM($C2:$L2)) -> 193826 | N2: =IF($A2="","",SUM($C2:$L2)) -> 193826 | O2: 0 | P2: =IF($A2="","",$M2-$N2-$O2) -> 0
M3: =IF($A3="","",SUM($C3:$L3)) | N3: =IF($A3="","",SUM($C3:$L3)) | P3: =IF($A3="","",$M3-$N3-$O3)
M4: =IF($A4="","",SUM($C4:$L4)) | N4: =IF($A4="","",SUM($C4:$L4)) | P4: =IF($A4="","",$M4-$N4-$O4)
M5: =IF($A5="","",SUM($C5:$L5)) | N5: =IF($A5="","",SUM($C5:$L5)) | P5: =IF($A5="","",$M5-$N5-$O5)
M6: =IF($A6="","",SUM($C6:$L6)) | N6: =IF($A6="","",SUM($C6:$L6)) | P6: =IF($A6="","",$M6-$N6-$O6)
M7: =IF($A7="","",SUM($C7:$L7)) | N7: =IF($A7="","",SUM($C7:$L7)) | P7: =IF($A7="","",$M7-$N7-$O7)
M8: =IF($A8="","",SUM($C8:$L8)) | N8: =IF($A8="","",SUM($C8:$L8)) | P8: =IF($A8="","",$M8-$N8-$O8)
M9: =IF($A9="","",SUM($C9:$L9)) | N9: =IF($A9="","",SUM($C9:$L9)) | P9: =IF($A9="","",$M9-$N9-$O9)
M10: =IF($A10="","",SUM($C10:$L10)) | N10: =IF($A10="","",SUM($C10:$L10)) | P10: =IF($A10="","",$M10-$N10-$O10)
M11: =IF($A11="","",SUM($C11:$L11)) | N11: =IF($A11="","",SUM($C11:$L11)) | P11: =IF($A11="","",$M11-$N11-$O11)
M12: =IF($A12="","",SUM($C12:$L12)) | N12: =IF($A12="","",SUM($C12:$L12)) | P12: =IF($A12="","",$M12-$N12-$O12)
M13: =IF($A13="","",SUM($C13:$L13)) | N13: =IF($A13="","",SUM($C13:$L13)) | P13: =IF($A13="","",$M13-$N13-$O13)
M14: =IF($A14="","",SUM($C14:$L14)) | N14: =IF($A14="","",SUM($C14:$L14)) | P14: =IF($A14="","",$M14-$N14-$O14)
... M503: =IF($A503="","",SUM($C503:$L503)) | N503: =IF($A503="","",SUM($C503:$L503)) | P503: =IF($A503="","",$M503-$N503-$O503)

Sheet Monthly Summary
A1: CONIC — MONTHLY SUMMARY
A3: Selected Month | B3: =DATE('Monthly Dashboard'!$D$3,MATCH('Monthly Dashboard'!$B$3,Calc!$M$2:$M$13,0),1) -> 46266
A4: Select Month and Year on the Monthly Dashboard.
A5: ONLINE SALES | B5: =SUMIFS('Daily Sales & Expenses'!$B$2:$B$495,'Daily Sales & Expenses'!$A$2:$A$495,">="&$B$3,'Daily Sales & Expenses'!$A$2:$A$495,"<"&EDATE($B$3,1)) -> 226284
A6: CASH SALES | B6: =SUMIFS('Daily Sales & Expenses'!$C$2:$C$495,'Daily Sales & Expenses'!$A$2:$A$495,">="&$B$3,'Daily Sales & Expenses'!$A$2:$A$495,"<"&EDATE($B$3,1)) -> 18570
A7: TOTAL SALES | B7: =B5+B6 -> 244854
A8: PURCHASES
A9: =Settings!A7 -> RawDawg | B9: =SUMIFS('Weekly Purchases'!$C$2:$C$503,'Weekly Purchases'!$A$2:$A$503,">="&$B$3,'Weekly Purchases'!$A$2:$A$503,"<"&EDATE($B$3,1)) -> 64049
A10: =Settings!A8 -> Fetch | B10: =SUMIFS('Weekly Purchases'!$D$2:$D$503,'Weekly Purchases'!$A$2:$A$503,">="&$B$3,'Weekly Purchases'!$A$2:$A$503,"<"&EDATE($B$3,1)) -> 95077
A11: =Settings!A9 -> Nord | B11: =SUMIFS('Weekly Purchases'!$E$2:$E$503,'Weekly Purchases'!$A$2:$A$503,">="&$B$3,'Weekly Purchases'!$A$2:$A$503,"<"&EDATE($B$3,1)) -> 0
A12: =Settings!A10 -> Belucci | B12: =SUMIFS('Weekly Purchases'!$F$2:$F$503,'Weekly Purchases'!$A$2:$A$503,">="&$B$3,'Weekly Purchases'!$A$2:$A$503,"<"&EDATE($B$3,1)) -> 26500
A13: =Settings!A11 -> FoolHardy | B13: =SUMIFS('Weekly Purchases'!$G$2:$G$503,'Weekly Purchases'!$A$2:$A$503,">="&$B$3,'Weekly Purchases'!$A$2:$A$503,"<"&EDATE($B$3,1)) -> 0
A14: =Settings!A12 -> Core | B14: =SUMIFS('Weekly Purchases'!$H$2:$H$503,'Weekly Purchases'!$A$2:$A$503,">="&$B$3,'Weekly Purchases'!$A$2:$A$503,"<"&EDATE($B$3,1)) -> 0
A15: =Settings!A13 -> Dexer | B15: =SUMIFS('Weekly Purchases'!$I$2:$I$503,'Weekly Purchases'!$A$2:$A$503,">="&$B$3,'Weekly Purchases'!$A$2:$A$503,"<"&EDATE($B$3,1)) -> 0
A16: =Settings!A14 -> Nordich | B16: =SUMIFS('Weekly Purchases'!$J$2:$J$503,'Weekly Purchases'!$A$2:$A$503,">="&$B$3,'Weekly Purchases'!$A$2:$A$503,"<"&EDATE($B$3,1)) -> 0
A17: =Settings!A15 -> Never | B17: =SUMIFS('Weekly Purchases'!$K$2:$K$503,'Weekly Purchases'!$A$2:$A$503,">="&$B$3,'Weekly Purchases'!$A$2:$A$503,"<"&EDATE($B$3,1)) -> 0
A18: =Settings!A16 -> Ozaro | B18: =SUMIFS('Weekly Purchases'!$L$2:$L$503,'Weekly Purchases'!$A$2:$A$503,">="&$B$3,'Weekly Purchases'!$A$2:$A$503,"<"&EDATE($B$3,1)) -> 8200
A19: Total Purchase | B19: =SUM(B9:B18) -> 193826
A20: EXPENSES
A21: Police | B21: =SUMIFS('Daily Sales & Expenses'!$E$2:$E$495,'Daily Sales & Expenses'!$A$2:$A$495,">="&$B$3,'Daily Sales & Expenses'!$A$2:$A$495,"<"&EDATE($B$3,1)) -> 11200
A22: Shop | B22: =SUMIFS('Daily Sales & Expenses'!$F$2:$F$495,'Daily Sales & Expenses'!$A$2:$A$495,">="&$B$3,'Daily Sales & Expenses'!$A$2:$A$495,"<"&EDATE($B$3,1)) -> 2949
A23: Transport | B23: =SUMIFS('Daily Sales & Expenses'!$G$2:$G$495,'Daily Sales & Expenses'!$A$2:$A$495,">="&$B$3,'Daily Sales & Expenses'!$A$2:$A$495,"<"&EDATE($B$3,1)) -> 4475
A24: Other | B24: =SUMIFS('Daily Sales & Expenses'!$H$2:$H$495,'Daily Sales & Expenses'!$A$2:$A$495,">="&$B$3,'Daily Sales & Expenses'!$A$2:$A$495,"<"&EDATE($B$3,1)) -> 4618
A25: Total Expenses | B25: =SUM(B21:B24) -> 23242
A26: BALANCES
A27: Opening Online Balance | B27: =Settings!$B$3+SUMIFS('Daily Sales & Expenses'!$B$2:$B$495,'Daily Sales & Expenses'!$A$2:$A$495,"<"&$B$3)-SUMIFS('Daily Sales & Expenses'!$J$2:$J$495,'Daily Sales & Expenses'!$A$2:$A$495,"<"&$B$3)-SUMIFS('Weekly Purchases'!$N$2:$N$503,'Weekly Purchases'!$B$2:$B$503,"<"&$B$3,'Weekly Purchases'!$B$2:$B$503,"<>")-SUMIFS('Weekly Purchases'!$N$2:$N$503,'Weekly Purchases'!$B$2:$B$503,"",'Weekly Purchases'!$A$2:$A$503,"<"&$B$3) -> 0
A28: Closing Online Balance | B28: =B27+B5-SUMIFS('Daily Sales & Expenses'!$J$2:$J$495,'Daily Sales & Expenses'!$A$2:$A$495,">="&$B$3,'Daily Sales & Expenses'!$A$2:$A$495,"<"&EDATE($B$3,1))-SUMIFS('Weekly Purchases'!$N$2:$N$503,'Weekly Purchases'!$B$2:$B$503,">="&$B$3,'Weekly Purchases'!$B$2:$B$503,"<"&EDATE($B$3,1),'Weekly Purchases'!$B$2:$B$503,"<>")-SUMIFS('Weekly Purchases'!$N$2:$N$503,'Weekly Purchases'!$B$2:$B$503,"",'Weekly Purchases'!$A$2:$A$503,">="&$B$3,'Weekly Purchases'!$A$2:$A$503,"<"&EDATE($B$3,1)) -> 9216
A29: Opening Cash Balance | B29: =Settings!$B$4+SUMIFS('Daily Sales & Expenses'!$C$2:$C$495,'Daily Sales & Expenses'!$A$2:$A$495,"<"&$B$3)-SUMIFS('Daily Sales & Expenses'!$K$2:$K$495,'Daily Sales & Expenses'!$A$2:$A$495,"<"&$B$3)-SUMIFS('Weekly Purchases'!$O$2:$O$503,'Weekly Purchases'!$B$2:$B$503,"<"&$B$3,'Weekly Purchases'!$B$2:$B$503,"<>")-SUMIFS('Weekly Purchases'!$O$2:$O$503,'Weekly Purchases'!$B$2:$B$503,"",'Weekly Purchases'!$A$2:$A$503,"<"&$B$3) -> 0
A30: Closing Cash Balance | B30: =B29+B6-SUMIFS('Daily Sales & Expenses'!$K$2:$K$495,'Daily Sales & Expenses'!$A$2:$A$495,">="&$B$3,'Daily Sales & Expenses'!$A$2:$A$495,"<"&EDATE($B$3,1))-SUMIFS('Weekly Purchases'!$O$2:$O$503,'Weekly Purchases'!$B$2:$B$503,">="&$B$3,'Weekly Purchases'!$B$2:$B$503,"<"&EDATE($B$3,1),'Weekly Purchases'!$B$2:$B$503,"<>")-SUMIFS('Weekly Purchases'!$O$2:$O$503,'Weekly Purchases'!$B$2:$B$503,"",'Weekly Purchases'!$A$2:$A$503,">="&$B$3,'Weekly Purchases'!$A$2:$A$503,"<"&EDATE($B$3,1)) -> 18570
A31: Total Closing Balance | B31: =B28+B30 -> 27786
A32: BUSINESS RESULT
A33: Net Amount | B33: =B7-B19-B25 -> 27786

Sheet Settings
A1: CONIC — SETTINGS
A3: Opening Online Balance | B3: 0
A4: Opening Cash Balance | B4: 0
A6: Vendor Master List | C6: Expense Categories
A7: RawDawg | C7: Police
A8: Fetch | C8: Shop
A9: Nord | C9: Transport
A10: Belucci | C10: Other
A11: FoolHardy
A12: Core
A13: Dexer
A14: Nordich
A15: Never
A16: Ozaro

Sheet Calc
A1: MonthList | B1: YearList | D1: Metric | E1: Amount | G1: Metric | H1: Amount | J1: Vendor | K1: Purchases | M1: Month | N1: Sales | O1: Purchases | P1: Expenses | Q1: Net Amount | R1: Closing Balance
A2: 43831 | B2: 2020 | D2: Online Sales | E2: ='Monthly Summary'!B5 -> 226284 | G2: Sales | H2: ='Monthly Summary'!B7 -> 244854 | J2: =Settings!A7 -> RawDawg | K2: ='Monthly Summary'!B9 -> 64049 | M2: January | N2: ='Yearly Dashboard'!B6 -> 0 | O2: ='Yearly Dashboard'!C6 -> 0 | P2: ='Yearly Dashboard'!D6 -> 0 | Q2: ='Yearly Dashboard'!E6 -> 0 | R2: ='Yearly Dashboard'!F6 -> 0
A3: 43862 | B3: 2021 | D3: Cash Sales | E3: ='Monthly Summary'!B6 -> 18570 | G3: Purchases | H3: ='Monthly Summary'!B19 -> 193826 | J3: =Settings!A8 -> Fetch | K3: ='Monthly Summary'!B10 -> 95077 | M3: February | N3: ='Yearly Dashboard'!B7 -> 0 | O3: ='Yearly Dashboard'!C7 -> 0 | P3: ='Yearly Dashboard'!D7 -> 0 | Q3: ='Yearly Dashboard'!E7 -> 0 | R3: ='Yearly Dashboard'!F7 -> 0
A4: 43891 | B4: 2022 | D4: Total Sales | E4: ='Monthly Summary'!B7 -> 244854 | G4: Expenses | H4: ='Monthly Summary'!B25 -> 23242 | J4: =Settings!A9 -> Nord | K4: ='Monthly Summary'!B11 -> 0 | M4: March | N4: ='Yearly Dashboard'!B8 -> 0 | O4: ='Yearly Dashboard'!C8 -> 0 | P4: ='Yearly Dashboard'!D8 -> 0 | Q4: ='Yearly Dashboard'!E8 -> 0 | R4: ='Yearly Dashboard'!F8 -> 0
A5: 43922 | B5: 2023 | J5: =Settings!A10 -> Belucci | K5: ='Monthly Summary'!B12 -> 26500 | M5: April | N5: ='Yearly Dashboard'!B9 -> 0 | O5: ='Yearly Dashboard'!C9 -> 0 | P5: ='Yearly Dashboard'!D9 -> 0 | Q5: ='Yearly Dashboard'!E9 -> 0 | R5: ='Yearly Dashboard'!F9 -> 0
A6: 43952 | B6: 2024 | J6: =Settings!A11 -> FoolHardy | K6: ='Monthly Summary'!B13 -> 0 | M6: May | N6: ='Yearly Dashboard'!B10 -> 0 | O6: ='Yearly Dashboard'!C10 -> 0 | P6: ='Yearly Dashboard'!D10 -> 0 | Q6: ='Yearly Dashboard'!E10 -> 0 | R6: ='Yearly Dashboard'!F10 -> 0
A7: 43983 | B7: 2025 | J7: =Settings!A12 -> Core | K7: ='Monthly Summary'!B14 -> 0 | M7: June | N7: ='Yearly Dashboard'!B11 -> 0 | O7: ='Yearly Dashboard'!C11 -> 0 | P7: ='Yearly Dashboard'!D11 -> 0 | Q7: ='Yearly Dashboard'!E11 -> 0 | R7: ='Yearly Dashboard'!F11 -> 0
A8: 44013 | B8: 2026 | J8: =Settings!A13 -> Dexer | K8: ='Monthly Summary'!B15 -> 0 | M8: July | N8: ='Yearly Dashboard'!B12 -> 0 | O8: ='Yearly Dashboard'!C12 -> 0 | P8: ='Yearly Dashboard'!D12 -> 0 | Q8: ='Yearly Dashboard'!E12 -> 0 | R8: ='Yearly Dashboard'!F12 -> 0
A9: 44044 | B9: 2027 | J9: =Settings!A14 -> Nordich | K9: ='Monthly Summary'!B16 -> 0 | M9: August | N9: ='Yearly Dashboard'!B13 -> 0 | O9: ='Yearly Dashboard'!C13 -> 0 | P9: ='Yearly Dashboard'!D13 -> 0 | Q9: ='Yearly Dashboard'!E13 -> 0 | R9: ='Yearly Dashboard'!F13 -> 0
A10: 44075 | B10: 2028 | J10: =Settings!A15 -> Never | K10: ='Monthly Summary'!B17 -> 0 | M10: September | N10: ='Yearly Dashboard'!B14 -> 244854 | O10: ='Yearly Dashboard'!C14 -> 193826 | P10: ='Yearly Dashboard'!D14 -> 23242 | Q10: ='Yearly Dashboard'!E14 -> 27786 | R10: ='Yearly Dashboard'!F14 -> 27786
A11: 44105 | B11: 2029 | J11: =Settings!A16 -> Ozaro | K11: ='Monthly Summary'!B18 -> 8200 | M11: October | N11: ='Yearly Dashboard'!B15 -> 0 | O11: ='Yearly Dashboard'!C15 -> 0 | P11: ='Yearly Dashboard'!D15 -> 0 | Q11: ='Yearly Dashboard'!E15 -> 0 | R11: ='Yearly Dashboard'!F15 -> 27786
A12: 44136 | B12: 2030 | M12: November | N12: ='Yearly Dashboard'!B16 -> 0 | O12: ='Yearly Dashboard'!C16 -> 0 | P12: ='Yearly Dashboard'!D16 -> 0 | Q12: ='Yearly Dashboard'!E16 -> 0 | R12: ='Yearly Dashboard'!F16 -> 27786
